<?xml version="1.0" encoding="UTF-8"?>
<testng-results skipped="1" failed="1" ignored="8" total="11" passed="1">
  <reporter-output>
    <line>
      <![CDATA[Test succeed!!!]]>
    </line>
    <line>
      <![CDATA[Test Failed!!!]]>
    </line>
  </reporter-output>
  <suite name="Suite" duration-ms="1156" started-at="2019-01-29T13:57:40Z" finished-at="2019-01-29T13:57:41Z">
    <groups>
    </groups>
    <test name="Test" duration-ms="1156" started-at="2019-01-29T13:57:40Z" finished-at="2019-01-29T13:57:41Z">
      <class name="com.e2e.testcases.TC002">
        <test-method status="FAIL" signature="f()[pri:0, instance:com.e2e.testcases.TC002@5656be13]" name="f" duration-ms="196" started-at="2019-01-29T14:57:40Z" finished-at="2019-01-29T14:57:40Z">
          <exception class="java.lang.AssertionError">
            <message>
              <![CDATA[Test failed expected [true] but found [false]]]>
            </message>
            <full-stacktrace>
              <![CDATA[java.lang.AssertionError: Test failed expected [true] but found [false]
	at org.testng.Assert.fail(Assert.java:93)
	at org.testng.Assert.failNotEquals(Assert.java:512)
	at org.testng.Assert.assertTrue(Assert.java:41)
	at com.e2e.testcases.TC002.f(TC002.java:19)
	at sun.reflect.NativeMethodAccessorImpl.invoke0(Native Method)
	at sun.reflect.NativeMethodAccessorImpl.invoke(NativeMethodAccessorImpl.java:62)
	at sun.reflect.DelegatingMethodAccessorImpl.invoke(DelegatingMethodAccessorImpl.java:43)
	at java.lang.reflect.Method.invoke(Method.java:498)
	at org.testng.internal.MethodInvocationHelper.invokeMethod(MethodInvocationHelper.java:108)
	at org.testng.internal.Invoker.invokeMethod(Invoker.java:661)
	at org.testng.internal.Invoker.invokeTestMethod(Invoker.java:869)
	at org.testng.internal.Invoker.invokeTestMethods(Invoker.java:1193)
	at org.testng.internal.TestMethodWorker.invokeTestMethods(TestMethodWorker.java:126)
	at org.testng.internal.TestMethodWorker.run(TestMethodWorker.java:109)
	at org.testng.TestRunner.privateRun(TestRunner.java:744)
	at org.testng.TestRunner.run(TestRunner.java:602)
	at org.testng.SuiteRunner.runTest(SuiteRunner.java:380)
	at org.testng.SuiteRunner.runSequentially(SuiteRunner.java:375)
	at org.testng.SuiteRunner.privateRun(SuiteRunner.java:340)
	at org.testng.SuiteRunner.run(SuiteRunner.java:289)
	at org.testng.SuiteRunnerWorker.runSuite(SuiteRunnerWorker.java:52)
	at org.testng.SuiteRunnerWorker.run(SuiteRunnerWorker.java:86)
	at org.testng.TestNG.runSuitesSequentially(TestNG.java:1301)
	at org.testng.TestNG.runSuitesLocally(TestNG.java:1226)
	at org.testng.TestNG.runSuites(TestNG.java:1144)
	at org.testng.TestNG.run(TestNG.java:1115)
	at org.apache.maven.surefire.testng.TestNGExecutor.run(TestNGExecutor.java:295)
	at org.apache.maven.surefire.testng.TestNGXmlTestSuite.execute(TestNGXmlTestSuite.java:84)
	at org.apache.maven.surefire.testng.TestNGProvider.invoke(TestNGProvider.java:90)
	at org.apache.maven.surefire.booter.ForkedBooter.invokeProviderInSameClassLoader(ForkedBooter.java:203)
	at org.apache.maven.surefire.booter.ForkedBooter.runSuitesInProcess(ForkedBooter.java:155)
	at org.apache.maven.surefire.booter.ForkedBooter.main(ForkedBooter.java:103)
]]>
            </full-stacktrace>
          </exception> <!-- java.lang.AssertionError -->
          <reporter-output>
            <line>
              <![CDATA[Test Failed!!!]]>
            </line>
          </reporter-output>
        </test-method> <!-- f -->
      </class> <!-- com.e2e.testcases.TC002 -->
      <class name="com.e2e.testcases.TC001">
        <test-method status="PASS" signature="beforeMethod()[pri:0, instance:com.e2e.testcases.TC001@235834f2]" name="beforeMethod" is-config="true" duration-ms="7332" started-at="2019-01-29T14:57:32Z" finished-at="2019-01-29T14:57:40Z">
          <reporter-output>
          </reporter-output>
        </test-method> <!-- beforeMethod -->
        <test-method status="PASS" signature="beforeSuite()[pri:0, instance:com.e2e.testcases.TC001@235834f2]" name="beforeSuite" is-config="true" duration-ms="1" started-at="2019-01-29T14:57:40Z" finished-at="2019-01-29T14:57:40Z">
          <reporter-output>
          </reporter-output>
        </test-method> <!-- beforeSuite -->
        <test-method status="PASS" signature="f()[pri:0, instance:com.e2e.testcases.TC001@235834f2]" name="f" duration-ms="388" started-at="2019-01-29T14:57:40Z" finished-at="2019-01-29T14:57:40Z">
          <reporter-output>
            <line>
              <![CDATA[Test succeed!!!]]>
            </line>
          </reporter-output>
        </test-method> <!-- f -->
        <test-method status="PASS" signature="afterMethod()[pri:0, instance:com.e2e.testcases.TC001@235834f2]" name="afterMethod" is-config="true" duration-ms="1395" started-at="2019-01-29T14:57:41Z" finished-at="2019-01-29T14:57:42Z">
          <reporter-output>
          </reporter-output>
        </test-method> <!-- afterMethod -->
        <test-method status="PASS" signature="afterSuite()[pri:0, instance:com.e2e.testcases.TC001@235834f2]" name="afterSuite" is-config="true" duration-ms="1" started-at="2019-01-29T14:57:42Z" finished-at="2019-01-29T14:57:42Z">
          <reporter-output>
          </reporter-output>
        </test-method> <!-- afterSuite -->
      </class> <!-- com.e2e.testcases.TC001 -->
      <class name="com.e2e.testcases.TC003">
        <test-method status="SKIP" signature="f(java.lang.String, java.lang.String)[pri:0, instance:com.e2e.testcases.TC003@4218d6a3]" name="f" duration-ms="0" started-at="2019-01-29T14:57:41Z" data-provider="getData" finished-at="2019-01-29T14:57:41Z">
          <exception class="java.lang.RuntimeException">
            <message>
              <![CDATA[java.lang.NegativeArraySizeException]]>
            </message>
            <full-stacktrace>
              <![CDATA[java.lang.RuntimeException: java.lang.NegativeArraySizeException
	at org.testng.internal.MethodInvocationHelper.invokeMethodNoCheckedException(MethodInvocationHelper.java:49)
	at org.testng.internal.MethodInvocationHelper.invokeDataProvider(MethodInvocationHelper.java:115)
	at org.testng.internal.Parameters.handleParameters(Parameters.java:509)
	at org.testng.internal.Invoker.handleParameters(Invoker.java:1308)
	at org.testng.internal.Invoker.createParameters(Invoker.java:1036)
	at org.testng.internal.Invoker.invokeTestMethods(Invoker.java:1126)
	at org.testng.internal.TestMethodWorker.invokeTestMethods(TestMethodWorker.java:126)
	at org.testng.internal.TestMethodWorker.run(TestMethodWorker.java:109)
	at org.testng.TestRunner.privateRun(TestRunner.java:744)
	at org.testng.TestRunner.run(TestRunner.java:602)
	at org.testng.SuiteRunner.runTest(SuiteRunner.java:380)
	at org.testng.SuiteRunner.runSequentially(SuiteRunner.java:375)
	at org.testng.SuiteRunner.privateRun(SuiteRunner.java:340)
	at org.testng.SuiteRunner.run(SuiteRunner.java:289)
	at org.testng.SuiteRunnerWorker.runSuite(SuiteRunnerWorker.java:52)
	at org.testng.SuiteRunnerWorker.run(SuiteRunnerWorker.java:86)
	at org.testng.TestNG.runSuitesSequentially(TestNG.java:1301)
	at org.testng.TestNG.runSuitesLocally(TestNG.java:1226)
	at org.testng.TestNG.runSuites(TestNG.java:1144)
	at org.testng.TestNG.run(TestNG.java:1115)
	at org.apache.maven.surefire.testng.TestNGExecutor.run(TestNGExecutor.java:295)
	at org.apache.maven.surefire.testng.TestNGXmlTestSuite.execute(TestNGXmlTestSuite.java:84)
	at org.apache.maven.surefire.testng.TestNGProvider.invoke(TestNGProvider.java:90)
	at org.apache.maven.surefire.booter.ForkedBooter.invokeProviderInSameClassLoader(ForkedBooter.java:203)
	at org.apache.maven.surefire.booter.ForkedBooter.runSuitesInProcess(ForkedBooter.java:155)
	at org.apache.maven.surefire.booter.ForkedBooter.main(ForkedBooter.java:103)
Caused by: java.lang.NegativeArraySizeException
	at com.e2e.testcases.TC003.getData(TC003.java:27)
	at sun.reflect.NativeMethodAccessorImpl.invoke0(Native Method)
	at sun.reflect.NativeMethodAccessorImpl.invoke(NativeMethodAccessorImpl.java:62)
	at sun.reflect.DelegatingMethodAccessorImpl.invoke(DelegatingMethodAccessorImpl.java:43)
	at java.lang.reflect.Method.invoke(Method.java:498)
	at org.testng.internal.MethodInvocationHelper.invokeMethod(MethodInvocationHelper.java:108)
	at org.testng.internal.MethodInvocationHelper.invokeMethod(MethodInvocationHelper.java:55)
	at org.testng.internal.MethodInvocationHelper.invokeMethodNoCheckedException(MethodInvocationHelper.java:45)
	... 25 more
]]>
            </full-stacktrace>
          </exception> <!-- java.lang.RuntimeException -->
          <reporter-output>
          </reporter-output>
        </test-method> <!-- f -->
      </class> <!-- com.e2e.testcases.TC003 -->
    </test> <!-- Test -->
  </suite> <!-- Suite -->
</testng-results>
